unload SINGULARITY/3.6.4 (PATH)
load SINGULARITY/3.6.4 (PATH)
/opt/amdgpu/share/libdrm/amdgpu.ids: No such file or directory
/opt/amdgpu/share/libdrm/amdgpu.ids: No such file or directory
/opt/amdgpu/share/libdrm/amdgpu.ids: No such file or directory
/opt/amdgpu/share/libdrm/amdgpu.ids: No such file or directory
Traceback (most recent call last):
  File "/usr/local/lib/python3.9/site-packages/urllib3/connection.py", line 198, in _new_conn
    sock = connection.create_connection(
  File "/usr/local/lib/python3.9/site-packages/urllib3/util/connection.py", line 85, in create_connection
    raise err
  File "/usr/local/lib/python3.9/site-packages/urllib3/util/connection.py", line 73, in create_connection
    sock.connect(sa)
OSError: [Errno 101] Network is unreachable

The above exception was the direct cause of the following exception:

Traceback (most recent call last):
  File "/usr/local/lib/python3.9/site-packages/urllib3/connectionpool.py", line 793, in urlopen
    response = self._make_request(
  File "/usr/local/lib/python3.9/site-packages/urllib3/connectionpool.py", line 491, in _make_request
    raise new_e
  File "/usr/local/lib/python3.9/site-packages/urllib3/connectionpool.py", line 467, in _make_request
    self._validate_conn(conn)
  File "/usr/local/lib/python3.9/site-packages/urllib3/connectionpool.py", line 1099, in _validate_conn
    conn.connect()
  File "/usr/local/lib/python3.9/site-packages/urllib3/connection.py", line 616, in connect
    self.sock = sock = self._new_conn()
  File "/usr/local/lib/python3.9/site-packages/urllib3/connection.py", line 213, in _new_conn
    raise NewConnectionError(
urllib3.exceptions.NewConnectionError: <urllib3.connection.HTTPSConnection object at 0x7fc83e10c370>: Failed to establish a new connection: [Errno 101] Network is unreachable

The above exception was the direct cause of the following exception:

Traceback (most recent call last):
  File "/usr/local/lib/python3.9/site-packages/requests/adapters.py", line 486, in send
    resp = conn.urlopen(
  File "/usr/local/lib/python3.9/site-packages/urllib3/connectionpool.py", line 847, in urlopen
    retries = retries.increment(
  File "/usr/local/lib/python3.9/site-packages/urllib3/util/retry.py", line 515, in increment
    raise MaxRetryError(_pool, url, reason) from reason  # type: ignore[arg-type]
urllib3.exceptions.MaxRetryError: HTTPSConnectionPool(host='huggingface.co', port=443): Max retries exceeded with url: /openai/whisper-small/resolve/main/preprocessor_config.json (Caused by NewConnectionError('<urllib3.connection.HTTPSConnection object at 0x7fc83e10c370>: Failed to establish a new connection: [Errno 101] Network is unreachable'))

During handling of the above exception, another exception occurred:

Traceback (most recent call last):
  File "/home/bsc88/bsc88135/.local/lib/python3.9/site-packages/huggingface_hub/file_download.py", line 1247, in hf_hub_download
    metadata = get_hf_file_metadata(
  File "/home/bsc88/bsc88135/.local/lib/python3.9/site-packages/huggingface_hub/utils/_validators.py", line 118, in _inner_fn
    return fn(*args, **kwargs)
  File "/home/bsc88/bsc88135/.local/lib/python3.9/site-packages/huggingface_hub/file_download.py", line 1624, in get_hf_file_metadata
    r = _request_wrapper(
  File "/home/bsc88/bsc88135/.local/lib/python3.9/site-packages/huggingface_hub/file_download.py", line 402, in _request_wrapper
    response = _request_wrapper(
  File "/home/bsc88/bsc88135/.local/lib/python3.9/site-packages/huggingface_hub/file_download.py", line 425, in _request_wrapper
    response = get_session().request(method=method, url=url, **params)
  File "/usr/local/lib/python3.9/site-packages/requests/sessions.py", line 589, in request
    resp = self.send(prep, **send_kwargs)
  File "/usr/local/lib/python3.9/site-packages/requests/sessions.py", line 703, in send
    r = adapter.send(request, **kwargs)
  File "/home/bsc88/bsc88135/.local/lib/python3.9/site-packages/huggingface_hub/utils/_http.py", line 63, in send
    return super().send(request, *args, **kwargs)
  File "/usr/local/lib/python3.9/site-packages/requests/adapters.py", line 519, in send
    raise ConnectionError(e, request=request)
requests.exceptions.ConnectionError: (MaxRetryError("HTTPSConnectionPool(host='huggingface.co', port=443): Max retries exceeded with url: /openai/whisper-small/resolve/main/preprocessor_config.json (Caused by NewConnectionError('<urllib3.connection.HTTPSConnection object at 0x7fc83e10c370>: Failed to establish a new connection: [Errno 101] Network is unreachable'))"), '(Request ID: 32333435-4628-41c1-b160-00e9ef8cff8f)')

The above exception was the direct cause of the following exception:

Traceback (most recent call last):
  File "/home/bsc88/bsc88135/.local/lib/python3.9/site-packages/transformers/utils/hub.py", line 417, in cached_file
    resolved_file = hf_hub_download(
  File "/home/bsc88/bsc88135/.local/lib/python3.9/site-packages/huggingface_hub/utils/_validators.py", line 118, in _inner_fn
    return fn(*args, **kwargs)
  File "/home/bsc88/bsc88135/.local/lib/python3.9/site-packages/huggingface_hub/file_download.py", line 1377, in hf_hub_download
    raise LocalEntryNotFoundError(
huggingface_hub.utils._errors.LocalEntryNotFoundError: An error happened while trying to locate the file on the Hub and we cannot find the requested files in the local cache. Please check your connection and try again or make sure your Internet connection is on.

During handling of the above exception, another exception occurred:

Traceback (most recent call last):
  File "/gpfs/projects/bsc88/speech/asr/ft_whisper_v3/whisper_catala/src/main.py", line 11, in <module>
    main()
  File "/gpfs/projects/bsc88/speech/asr/ft_whisper_v3/whisper_catala/src/main.py", line 6, in main
    trainer = get_trainer()
  File "/gpfs/projects/bsc88/speech/asr/ft_whisper_v3/whisper_catala/src/train.py", line 24, in get_trainer
    processor = WhisperProcessor.from_pretrained(MODEL['name'], language=MODEL['language'], task=MODEL['task'])
  File "/home/bsc88/bsc88135/.local/lib/python3.9/site-packages/transformers/processing_utils.py", line 184, in from_pretrained
    args = cls._get_arguments_from_pretrained(pretrained_model_name_or_path, **kwargs)
  File "/home/bsc88/bsc88135/.local/lib/python3.9/site-packages/transformers/processing_utils.py", line 228, in _get_arguments_from_pretrained
    args.append(attribute_class.from_pretrained(pretrained_model_name_or_path, **kwargs))
  File "/home/bsc88/bsc88135/.local/lib/python3.9/site-packages/transformers/feature_extraction_utils.py", line 330, in from_pretrained
    feature_extractor_dict, kwargs = cls.get_feature_extractor_dict(pretrained_model_name_or_path, **kwargs)
  File "/home/bsc88/bsc88135/.local/lib/python3.9/site-packages/transformers/feature_extraction_utils.py", line 430, in get_feature_extractor_dict
    resolved_feature_extractor_file = cached_file(
  File "/home/bsc88/bsc88135/.local/lib/python3.9/site-packages/transformers/utils/hub.py", line 452, in cached_file
    raise EnvironmentError(
OSError: We couldn't connect to 'https://huggingface.co' to load this file, couldn't find it in the cached files and it looks like openai/whisper-small is not the path to a directory containing a file named preprocessor_config.json.
Checkout your internet connection or see how to run the library in offline mode at 'https://huggingface.co/docs/transformers/installation#offline-mode'.
